<?xml version="1.0" encoding="utf-8"?>
<robot name="xamla_motion_examples" xmlns:xacro="http://ros.org/wiki/xacro" xmlns:xamla="http://www.xamla.com/">
  <link name="world" />
  <link name="torso_base_link">
    <visual>
      <geometry>
        <mesh filename="package://part_motoman_sda10f/visual/motoman_base.stl" />
      </geometry>
      <material name="blue">
        <color rgba="0 0 1 1" />
      </material>
    </visual>
    <collision>
      <geometry>
        <mesh filename="package://part_motoman_sda10f/collision/motoman_base.stl" />
      </geometry>
      <material name="yellow">
        <color rgba="0 1 1 1" />
      </material>
    </collision>
  </link>
  <link name="torso_link_b1">
    <visual>
      <origin rpy="0 0 0" xyz="0 0 -0.0165" />
      <geometry>
        <mesh filename="package://part_motoman_sda10f/visual/motoman_axis_b1.stl" />
      </geometry>
      <material name="silver">
        <color rgba="0.8 0.8 0.8 1" />
      </material>
    </visual>
    <collision>
      <origin rpy="0 0 0" xyz="0 0 -0.0165" />
      <geometry>
        <mesh filename="package://part_motoman_sda10f/collision/motoman_axis_b1.stl" />
      </geometry>
      <material name="yellow" />
    </collision>
  </link>
  <link name="torso_link_b2">
    <visual>
      <origin rpy="0 0 0" xyz="0 0 0" />
      <geometry>
        <mesh filename="package://part_motoman_sda10f/visual/motoman_axis_b1.stl" />
      </geometry>
      <material name="silver">
        <color rgba="0.8 0.8 0.8 1" />
      </material>
    </visual>
    <collision>
      <origin rpy="0 0 0" xyz="0 0 0" />
      <geometry>
        <mesh filename="package://part_motoman_sda10f/collision/motoman_axis_b1.stl" />
      </geometry>
      <material name="yellow" />
    </collision>
  </link>
  <joint name="torso_joint_b1" type="revolute">
    <parent link="torso_base_link" />
    <child link="torso_link_b1" />
    <origin xyz="0.0925 0 0.9" rpy="0 0 0" />
    <axis xyz="0 0 1" />
    <limit lower="-2.82833" upper="2.82833" effort="100" velocity="2.26" />
  </joint>
  <joint name="torso_joint_b2" type="revolute">
    <parent link="torso_base_link" />
    <child link="torso_link_b2" />
    <origin xyz="0.09257 0 0.8835" rpy="0 0 0" />
    <axis xyz="0 0 1" />
    <limit lower="-2.82833" upper="2.82833" effort="100" velocity="2.26" />
    <mimic joint="torso_joint_b1" multiplier="1" offset="0" />
  </joint>
  <joint name="torso_base_joint" type="fixed">
    <parent link="world" />
    <child link="torso_base_link" />
    <origin xyz="0 0 0" rpy="0 0 0" />
  </joint>
  <link name="arm_left_link_1_s">
    <visual>
      <origin rpy="0 0 0" xyz="0 0 0" />
      <geometry>
        <mesh filename="package://part_motoman_sda10f/visual/motoman_axis_s.stl" />
      </geometry>
      <material name="blue">
        <color rgba="0.8 0.8 0.8 1" />
      </material>
    </visual>
    <collision>
      <origin rpy="0 0 0" xyz="0 0 0" />
      <geometry>
        <mesh filename="package://part_motoman_sda10f/collision/motoman_axis_s.stl" />
      </geometry>
      <material name="yellow" />
    </collision>
  </link>
  <link name="arm_left_link_2_l">
    <visual>
      <origin rpy="0 0 0" xyz="0 0 0" />
      <geometry>
        <mesh filename="package://part_motoman_sda10f/visual/motoman_axis_l.stl" />
      </geometry>
      <material name="silver" />
    </visual>
    <collision>
      <origin rpy="0 0 0" xyz="0 0 0" />
      <geometry>
        <mesh filename="package://part_motoman_sda10f/collision/motoman_axis_l.stl" />
      </geometry>
      <material name="yellow" />
    </collision>
  </link>
  <link name="arm_left_link_3_e">
    <visual>
      <origin rpy="0 0 0" xyz="0 0 0" />
      <geometry>
        <mesh filename="package://part_motoman_sda10f/visual/motoman_axis_e.stl" />
      </geometry>
      <material name="blue" />
    </visual>
    <collision>
      <origin rpy="0 0 0" xyz="0 0 0" />
      <geometry>
        <mesh filename="package://part_motoman_sda10f/collision/motoman_axis_e.stl" />
      </geometry>
      <material name="yellow" />
    </collision>
  </link>
  <link name="arm_left_link_4_u">
    <visual>
      <origin rpy="0 0 0" xyz="0 0 0" />
      <geometry>
        <mesh filename="package://part_motoman_sda10f/visual/motoman_axis_u.stl" />
      </geometry>
      <material name="silver" />
    </visual>
    <collision>
      <origin rpy="0 0 0" xyz="0 0 0" />
      <geometry>
        <mesh filename="package://part_motoman_sda10f/collision/motoman_axis_u.stl" />
      </geometry>
      <material name="yellow" />
    </collision>
  </link>
  <link name="arm_left_link_5_r">
    <visual>
      <origin rpy="0 0 0" xyz="0 0 0" />
      <geometry>
        <mesh filename="package://part_motoman_sda10f/visual/motoman_axis_r.stl" />
      </geometry>
      <material name="blue" />
    </visual>
    <collision>
      <origin rpy="0 0 0" xyz="0 0 0" />
      <geometry>
        <mesh filename="package://part_motoman_sda10f/collision/motoman_axis_r.stl" />
      </geometry>
      <material name="yellow" />
    </collision>
  </link>
  <link name="arm_left_link_6_b">
    <visual>
      <origin rpy="0 0 0" xyz="0 0 0" />
      <geometry>
        <mesh filename="package://part_motoman_sda10f/visual/motoman_axis_b.stl" />
      </geometry>
      <material name="silver" />
    </visual>
    <collision>
      <origin rpy="0 0 0" xyz="0 0 0" />
      <geometry>
        <mesh filename="package://part_motoman_sda10f/collision/motoman_axis_b.stl" />
      </geometry>
      <material name="yellow" />
    </collision>
  </link>
  <link name="arm_left_link_7_t">
    <visual>
      <geometry>
        <mesh filename="package://part_motoman_sda10f/visual/motoman_axis_t.stl" />
      </geometry>
      <material name="blue" />
    </visual>
    <collision>
      <geometry>
        <mesh filename="package://part_motoman_sda10f/collision/motoman_axis_t.stl" />
      </geometry>
      <material name="yellow" />
    </collision>
  </link>
  <link name="arm_left_link_tool0" />
  <joint name="arm_left_joint_1_s" type="revolute">
    <parent link="torso_link_b1" />
    <child link="arm_left_link_1_s" />
    <origin xyz="0.09996 0.0275 0.32214" rpy="1.5707963267949 0 0" />
    <axis xyz="0 0 -1" />
    <limit lower="-3.0986" upper="3.0986" effort="0" velocity="2.95" />
  </joint>
  <joint name="arm_left_joint_2_l" type="revolute">
    <parent link="arm_left_link_1_s" />
    <child link="arm_left_link_2_l" />
    <origin xyz="0 0.0577 -0.2255" rpy="-1.5707963267949 0 0" />
    <axis xyz="0 0 -1" />
    <limit lower="-1.8809" upper="1.8809" effort="0" velocity="2.95" />
  </joint>
  <joint name="arm_left_joint_3_e" type="revolute">
    <parent link="arm_left_link_2_l" />
    <child link="arm_left_link_3_e" />
    <origin xyz="0 0.1690 -0.0454" rpy="1.5707963267949 0 0" />
    <axis xyz="0 0 -1" />
    <limit lower="-2.9204" upper="2.9204" effort="0" velocity="2.95" />
  </joint>
  <joint name="arm_left_joint_4_u" type="revolute">
    <parent link="arm_left_link_3_e" />
    <child link="arm_left_link_4_u" />
    <origin xyz="0 -0.0085 -0.181" rpy="-1.5707963267949 0 0" />
    <axis xyz="0 0 1" />
    <limit lower="-2.3362999999999996" upper="2.3362999999999996" effort="0" velocity="2.95" />
  </joint>
  <joint name="arm_left_joint_5_r" type="revolute">
    <parent link="arm_left_link_4_u" />
    <child link="arm_left_link_5_r" />
    <origin xyz="0 0.1936 0.0155" rpy="1.5707963267949 0 0" />
    <axis xyz="0 0 1" />
    <limit lower="-3.0986" upper="3.0986" effort="0" velocity="3.48" />
  </joint>
  <joint name="arm_left_joint_6_b" type="revolute">
    <parent link="arm_left_link_5_r" />
    <child link="arm_left_link_6_b" />
    <origin xyz="0 0.0080 -0.155" rpy="-1.5707963267949 0 0" />
    <axis xyz="0 0 1" />
    <limit lower="-1.8809" upper="1.8809" effort="0" velocity="3.48" />
  </joint>
  <joint name="arm_left_joint_7_t" type="revolute">
    <parent link="arm_left_link_6_b" />
    <child link="arm_left_link_7_t" />
    <origin xyz="0 0.168 -0.015" rpy="1.5707963267949 0 0" />
    <axis xyz="0 0 1" />
    <limit lower="-3.0986" upper="3.0986" effort="0" velocity="6.97" />
  </joint>
  <joint name="arm_left_joint_tool0" type="fixed">
    <origin xyz="0 0 0.0" rpy="3.14159265358979 0 0" />
    <parent link="arm_left_link_7_t" />
    <child link="arm_left_link_tool0" />
  </joint>
  <link name="arm_right_link_1_s">
    <visual>
      <origin rpy="0 0 0" xyz="0 0 0" />
      <geometry>
        <mesh filename="package://part_motoman_sda10f/visual/motoman_axis_s.stl" />
      </geometry>
      <material name="blue">
        <color rgba="0.8 0.8 0.8 1" />
      </material>
    </visual>
    <collision>
      <origin rpy="0 0 0" xyz="0 0 0" />
      <geometry>
        <mesh filename="package://part_motoman_sda10f/collision/motoman_axis_s.stl" />
      </geometry>
      <material name="yellow" />
    </collision>
  </link>
  <link name="arm_right_link_2_l">
    <visual>
      <origin rpy="0 0 0" xyz="0 0 0" />
      <geometry>
        <mesh filename="package://part_motoman_sda10f/visual/motoman_axis_l.stl" />
      </geometry>
      <material name="silver" />
    </visual>
    <collision>
      <origin rpy="0 0 0" xyz="0 0 0" />
      <geometry>
        <mesh filename="package://part_motoman_sda10f/collision/motoman_axis_l.stl" />
      </geometry>
      <material name="yellow" />
    </collision>
  </link>
  <link name="arm_right_link_3_e">
    <visual>
      <origin rpy="0 0 0" xyz="0 0 0" />
      <geometry>
        <mesh filename="package://part_motoman_sda10f/visual/motoman_axis_e.stl" />
      </geometry>
      <material name="blue" />
    </visual>
    <collision>
      <origin rpy="0 0 0" xyz="0 0 0" />
      <geometry>
        <mesh filename="package://part_motoman_sda10f/collision/motoman_axis_e.stl" />
      </geometry>
      <material name="yellow" />
    </collision>
  </link>
  <link name="arm_right_link_4_u">
    <visual>
      <origin rpy="0 0 0" xyz="0 0 0" />
      <geometry>
        <mesh filename="package://part_motoman_sda10f/visual/motoman_axis_u.stl" />
      </geometry>
      <material name="silver" />
    </visual>
    <collision>
      <origin rpy="0 0 0" xyz="0 0 0" />
      <geometry>
        <mesh filename="package://part_motoman_sda10f/collision/motoman_axis_u.stl" />
      </geometry>
      <material name="yellow" />
    </collision>
  </link>
  <link name="arm_right_link_5_r">
    <visual>
      <origin rpy="0 0 0" xyz="0 0 0" />
      <geometry>
        <mesh filename="package://part_motoman_sda10f/visual/motoman_axis_r.stl" />
      </geometry>
      <material name="blue" />
    </visual>
    <collision>
      <origin rpy="0 0 0" xyz="0 0 0" />
      <geometry>
        <mesh filename="package://part_motoman_sda10f/collision/motoman_axis_r.stl" />
      </geometry>
      <material name="yellow" />
    </collision>
  </link>
  <link name="arm_right_link_6_b">
    <visual>
      <origin rpy="0 0 0" xyz="0 0 0" />
      <geometry>
        <mesh filename="package://part_motoman_sda10f/visual/motoman_axis_b.stl" />
      </geometry>
      <material name="silver" />
    </visual>
    <collision>
      <origin rpy="0 0 0" xyz="0 0 0" />
      <geometry>
        <mesh filename="package://part_motoman_sda10f/collision/motoman_axis_b.stl" />
      </geometry>
      <material name="yellow" />
    </collision>
  </link>
  <link name="arm_right_link_7_t">
    <visual>
      <geometry>
        <mesh filename="package://part_motoman_sda10f/visual/motoman_axis_t.stl" />
      </geometry>
      <material name="blue" />
    </visual>
    <collision>
      <geometry>
        <mesh filename="package://part_motoman_sda10f/collision/motoman_axis_t.stl" />
      </geometry>
      <material name="yellow" />
    </collision>
  </link>
  <link name="arm_right_link_tool0" />
  <joint name="arm_right_joint_1_s" type="revolute">
    <parent link="torso_link_b1" />
    <child link="arm_right_link_1_s" />
    <origin xyz="0.09996 -0.0275 0.32214" rpy="1.5707963267949 0 -3.14159265358979" />
    <axis xyz="0 0 1" />
    <limit lower="-3.0986" upper="3.0986" effort="0" velocity="2.95" />
  </joint>
  <joint name="arm_right_joint_2_l" type="revolute">
    <parent link="arm_right_link_1_s" />
    <child link="arm_right_link_2_l" />
    <origin xyz="0 0.0577 -0.2255" rpy="-1.5707963267949 0 0" />
    <axis xyz="0 0 1" />
    <limit lower="-1.8809" upper="1.8809" effort="0" velocity="2.95" />
  </joint>
  <joint name="arm_right_joint_3_e" type="revolute">
    <parent link="arm_right_link_2_l" />
    <child link="arm_right_link_3_e" />
    <origin xyz="0 0.1690 -0.0454" rpy="1.5707963267949 0 0" />
    <axis xyz="0 0 1" />
    <limit lower="-2.9204" upper="2.9204" effort="0" velocity="2.95" />
  </joint>
  <joint name="arm_right_joint_4_u" type="revolute">
    <parent link="arm_right_link_3_e" />
    <child link="arm_right_link_4_u" />
    <origin xyz="0 -0.0085 -0.181" rpy="-1.5707963267949 0 0" />
    <axis xyz="0 0 -1" />
    <limit lower="-2.3362999999999996" upper="2.3362999999999996" effort="0" velocity="2.95" />
  </joint>
  <joint name="arm_right_joint_5_r" type="revolute">
    <parent link="arm_right_link_4_u" />
    <child link="arm_right_link_5_r" />
    <origin xyz="0 0.1936 0.0155" rpy="1.5707963267949 0 0" />
    <axis xyz="0 0 -1" />
    <limit lower="-3.0986" upper="3.0986" effort="0" velocity="3.48" />
  </joint>
  <joint name="arm_right_joint_6_b" type="revolute">
    <parent link="arm_right_link_5_r" />
    <child link="arm_right_link_6_b" />
    <origin xyz="0 0.0080 -0.155" rpy="-1.5707963267949 0 0" />
    <axis xyz="0 0 -1" />
    <limit lower="-1.8809" upper="1.8809" effort="0" velocity="3.48" />
  </joint>
  <joint name="arm_right_joint_7_t" type="revolute">
    <parent link="arm_right_link_6_b" />
    <child link="arm_right_link_7_t" />
    <origin xyz="0 0.168 -0.015" rpy="1.5707963267949 0 0" />
    <axis xyz="0 0 -1" />
    <limit lower="-3.0986" upper="3.0986" effort="0" velocity="6.97" />
  </joint>
  <joint name="arm_right_joint_tool0" type="fixed">
    <origin xyz="0 0 0.0" rpy="3.14159265358979 0 0" />
    <parent link="arm_right_link_7_t" />
    <child link="arm_right_link_tool0" />
  </joint>
  <link name="_head_base"></link>
  <joint name="_base_2_head_base" type="fixed">
    <parent link="torso_link_b1" />
    <child link="_head_base" />
    <origin rpy="0 0 0.0" xyz="0.09996 0 0.441" />
  </joint>
  <joint name="_anterior_gripper_joint" type="fixed">
    <origin xyz="0 0 0" rpy="0 0 0" />
    <parent link="arm_right_link_tool0" />
    <child link="_base_link" />
  </joint>
  <link name="_base_link">
    <inertial>
      <mass value="0.25" />
      <origin xyz="0 0 0" />
      <!--inertia ixx="1.0" ixy="0.0" ixz="0.0"
               iyy="100.0" iyz="0.0"
               izz="1.0" /-->
      <inertia ixx="1.0" ixy="0.0" ixz="0.0" iyy="1.0" iyz="0.0" izz="1.0" />
    </inertial>
    <visual>
      <origin xyz="0.0 0 0" rpy="3.14159265358979 0 1.5707963267949" />
      <geometry>
        <mesh filename="package://part_wsg50/visual/wsg50_base.dae" scale="0.001 0.001 0.001" />
        <!--box size="0.146 0.05 0.0735"/-->
      </geometry>
      <material name="grey">
        <color rgba="0.5 0.5 0.5 1" />
      </material>
    </visual>
    <collision>
      <origin xyz="0.0 0 0" rpy="3.14159265358979 0 1.5707963267949" />
      <geometry>
        <!--box size="0.146 0.05 0.0735"/-->
        <mesh filename="package://part_wsg50/collision/wsg50_base.stl" scale="0.001 0.001 0.001" />
      </geometry>
    </collision>
  </link>
  <gazebo reference="_base_link">
    <material>Gazebo/Grey</material>
    <turnGravityOff>false</turnGravityOff>
  </gazebo>
  <joint name="_base_joint_gripper_left" type="prismatic">
    <limit lower="-0.055" upper="-0.0027" effort="80.0" velocity="0.42" />
    <origin xyz="0 0 0.0731" rpy="0 0 0" />
    <!--origin xyz="-0.0067 0 0.049" rpy="0 0 0" /-->
    <parent link="_base_link" />
    <child link="_gripper_left" />
    <dynamics friction="100" damping="100" />
    <axis xyz="-1 0 0" />
    <mimic joint="_base_joint_gripper_right" multiplier="-1.0" offset="0.0" />
  </joint>
  <transmission name="_base_trans_left" type="pr2_mechanism_model/SimpleTransmission">
    <actuator name="_base_motor_left" />
    <joint name="_base_joint_gripper_left" />
    <mechanicalReduction>1</mechanicalReduction>
    <motorTorqueConstant>1</motorTorqueConstant>
  </transmission>
  <link name="_gripper_left">
    <inertial>
      <mass value="0.1" />
      <origin xyz="0 0 0" />
      <inertia ixx="1.0" ixy="0.0" ixz="0.0" iyy="1.0" iyz="0.0" izz="1.0" />
    </inertial>
    <visual>
      <origin xyz="0.0 0 0" rpy="3.14159265358979 0 -1.5707963267949" />
      <geometry>
        <mesh filename="package://part_wsg50/visual/wsg50_base_gripper_left.dae" scale="0.001 0.001 0.001" />
        <!--box size="0.0175 0.03 0.024"/-->
      </geometry>
    </visual>
    <collision>
      <origin xyz="0 0 0" rpy="3.14159265358979 0 -1.5707963267949" />
      <geometry>
        <!--box size="0.0175 0.03 0.024"/-->
        <mesh filename="package://part_wsg50/collision/wsg50_base_gripper_left.stl" scale="0.001 0.001 0.001" />
      </geometry>
    </collision>
  </link>
  <gazebo reference="_gripper_left">
    <material>Gazebo/Blue</material>
    <turnGravityOff>false</turnGravityOff>
  </gazebo>
  <joint name="_base_joint_gripper_right" type="prismatic">
    <limit lower="0.0028" upper="0.0549" effort="80.0" velocity="0.42" />
    <origin xyz="0 0 0.0731" rpy="0 0 0" />
    <parent link="_base_link" />
    <child link="_gripper_right" />
    <axis xyz="-1 0 0" />
  </joint>
  <transmission name="_base_trans_right" type="pr2_mechanism_model/SimpleTransmission">
    <actuator name="_base_motor_right" />
    <joint name="_base_joint_gripper_right" />
    <mechanicalReduction>1</mechanicalReduction>
    <motorTorqueConstant>1</motorTorqueConstant>
  </transmission>
  <link name="_gripper_right">
    <inertial>
      <mass value="0.1" />
      <origin xyz="0 0 0" />
      <inertia ixx="1.0" ixy="0.0" ixz="0.0" iyy="1.0" iyz="0.0" izz="1.0" />
    </inertial>
    <visual>
      <origin xyz="0.0 0 0" rpy="3.14159265358979 0 -1.5707963267949" />
      <geometry>
        <mesh filename="package://part_wsg50/visual/wsg50_base_gripper_right.dae" scale="0.001 0.001 0.001" />
        <!--box size="0.0175 0.03 0.024"/-->
      </geometry>
    </visual>
    <collision>
      <origin xyz="0 0 0" rpy="3.14159265358979 0 -1.5707963267949" />
      <geometry>
        <!--box size="0.0175 0.03 0.024"/-->
        <mesh filename="package://part_wsg50/collision/wsg50_base_gripper_right.stl" scale="0.001 0.001 0.001" />
      </geometry>
    </collision>
  </link>
  <link name="_gripper_right_tool0" />
  <joint name="_base_joint_gripper_right_tool0" type="fixed">
    <origin xyz="-0.001 0 0.024" rpy="0 0 0" />
    <parent link="_gripper_right" />
    <child link="_gripper_right_tool0" />
  </joint>
  <link name="_gripper_left_tool0" />
  <joint name="_base_joint_gripper_left_tool0" type="fixed">
    <origin xyz="0.001 0 0.024" rpy="0 0 3.14159265358979" />
    <parent link="_gripper_left" />
    <child link="_gripper_left_tool0" />
  </joint>
  <gazebo reference="gripper_right">
    <material>Gazebo/White</material>
    <turnGravityOff>false</turnGravityOff>
  </gazebo>
  <link name="cell_body">
    <inertial>
      <mass value="1.0" />
      <!-- center of mass (com) is defined w.r.t. link local coordinate system -->
      <origin xyz="0.25 -0.5 0" />
      <inertia ixx="1.0" ixy="0.0" ixz="0.0" iyy="1.0" iyz="0.0" izz="1.0" />
    </inertial>
    <visual>
      <!-- visual origin is defined w.r.t. link local coordinate system -->
      <origin xyz="0 0 0" rpy="0 0 0" />
      <geometry>
        <mesh filename="package://part_sda10d_cell/visual/cell.dae" scale="1.00 1.00 1.00" />
      </geometry>
    </visual>
    <collision>
      <!-- collision origin is defined w.r.t. link local coordinate system -->
      <origin xyz="0 0 0" rpy="0 0 0" />
      <geometry>
        <mesh filename="package://part_sda10d_cell/collision/cell.stl" scale="1.00 1.00 1.00" />
      </geometry>
    </collision>
  </link>
  <link name="cell_tool0" />
  <joint name="world_to_cell_body" type="fixed">
    <parent link="world" />
    <child link="cell_body" />
    <origin xyz="0 0 0" rpy="0 0 0" />
  </joint>
  <joint name="cell_body_to_tool0" type="fixed">
    <parent link="cell_body" />
    <child link="cell_tool0" />
    <origin xyz="0 0 0.16" rpy="0 0 0" />
  </joint>
  <gazebo reference="cell_body">
    <material>Gazebo/LightWood</material>
  </gazebo>
</robot>